
<mujoco model="2-link arm position control">
  <option timestep="0.005" noslip_iterations="3"/>
  <include file="humanoid_muscle.xml"/>
  <worldbody>

    <body name="pass_body" pos="0.62 3.7 0">
      <geom density="3000" type="cylinder" fromto="0 0 0 0 0 2" size="0.06" rgba=".8 .2 .2 1"/>
      <joint type="slide" axis="0 1 0" limited="true" range="-100 0"/>
    </body>

    <body name="block_body"  pos="0.67 3.8 0">
      <geom density="900" type="cylinder" fromto="0 0 0 0 0 2" size="0.02" rgba=".2 .8 .2 1" friction="2"/>
      <joint type="slide" axis="0 1 0" limited="true" range="-100 0"/>
    </body>
  </worldbody>
  <keyframe>
    <key name="reach_imp" qpos="0 0 1.282
                            0 0 0 0
                            0 0 0
                            0 0 0 0 0 0
                            0 0 0 0 0 0
                            0.364 0.7 -1.7 0 0.75 -0.75 -1.4
                            0 0"/>
  </keyframe>

</mujoco>
